<?xml version="1.0" ?>
<!-- =================================================================================== -->
<!-- |    This document was autogenerated by xacro from /home/dmitriy/ros2_ws/src/penguin_robot/src/description/penguin_bot_description.urdf | -->
<!-- |    EDITING THIS FILE BY HAND IS NOT RECOMMENDED                                 | -->
<!-- =================================================================================== -->
<robot name="penguin_bot">
  <!-- Robot base(torso) -->
  <link name="base_link">
    <visual>
      <origin rpy="0.0 0.0 0.0" xyz="0.0 0.0 0.058"/>
      <geometry>
        <box size="0.36 0.16 0.1"/>
      </geometry>
      <material name="black">
        <color rgba="0.1 0.1 0.1 1.0"/>
      </material>
    </visual>
    <collision>
      <origin rpy="0.0 0.0 0.0" xyz="0.0 0.0 0.058"/>
      <geometry>
        <box size="0.36 0.16 0.1"/>
      </geometry>
    </collision>
    <inertial>
      <mass value="1.5"/>
      <origin rpy="0.0 0.0 0.0" xyz="0.0 0.0 0.058"/>
      <inertia ixx="0.0135" ixy="0.0" ixz="0.0" iyy="0.0178" iyz="0.0" izz="0.0086"/>
    </inertial>
  </link>
  <link name="base_footprint"/>
  <!-- Front Caster -->
  <link name="caster">
    <visual>
      <geometry>
        <sphere radius="0.016"/>
      </geometry>
      <material name="black">
        <color rgba="0.1 0.1 0.1 1.0"/>
      </material>
    </visual>
    <inertial>
      <mass value="0.03"/>
      <origin rpy="0 0 0" xyz="0 0 0"/>
      <inertia ixx="0.00000006" ixy="0.0" ixz="0.0" iyy="0.00000006" iyz="0.0" izz="0.00000006"/>
    </inertial>
  </link>
  <link name="head">
    <visual>
      <geometry>
        <sphere radius="0.05"/>
      </geometry>
      <material name="black">
        <color rgba="0.1 0.1 0.1 1.0"/>
      </material>
    </visual>
    <collision>
      <geometry>
        <sphere radius="0.05"/>
      </geometry>
    </collision>
    <inertial>
      <mass value="0.3"/>
      <origin rpy="0 0 0" xyz="0 0 0"/>
      <inertia ixx="0.0003" ixy="0.0" ixz="0.0" iyy="0.0003" iyz="0.0" izz="0.0003"/>
    </inertial>
  </link>
  <link name="beak">
    <visual>
      <geometry>
        <box size="0.05 0.01 0.01"/>
      </geometry>
      <material name="orange">
        <color rgba="1.0 0.6 0.0 1.0"/>
      </material>
    </visual>
    <collision>
      <geometry>
        <box size="0.05 0.01 0.01"/>
      </geometry>
    </collision>
    <inertial>
      <mass value="0.005"/>
      <origin rpy="0 0 0" xyz="0 0 0"/>
      <inertia ixx="0.00000002" ixy="0.0" ixz="0.0" iyy="0.00000001" iyz="0.0" izz="0.00000001"/>
    </inertial>
  </link>
  <link name="tail">
    <visual>
      <geometry>
        <box size="0.06 0.045 0.01"/>
      </geometry>
      <material name="black">
        <color rgba="0.1 0.1 0.1 1.0"/>
      </material>
    </visual>
    <collision>
      <geometry>
        <box size="0.06 0.045 0.01"/>
      </geometry>
    </collision>
    <inertial>
      <mass value="0.05"/>
      <origin rpy="0 0 0" xyz="0 0 0"/>
      <inertia ixx="0.000008" ixy="0.0" ixz="0.0" iyy="0.000002" iyz="0.0" izz="0.00001"/>
    </inertial>
  </link>
  <link name="rpg_base">
    <visual>
      <geometry>
        <box size="0.25 0.025 0.025"/>
      </geometry>
      <material name="green">
        <color rgba="0.05 0.2 0.0 1.0"/>
      </material>
    </visual>
    <collision>
      <geometry>
        <box size="0.25 0.025 0.025"/>
      </geometry>
    </collision>
    <inertial>
      <mass value="0.15"/>
      <origin rpy="0 0 0" xyz="0 0 0"/>
      <inertia ixx="0.00001" ixy="0.0" ixz="0.0" iyy="0.00008" iyz="0.0" izz="0.00008"/>
    </inertial>
  </link>
  <link name="rpg_front">
    <visual>
      <geometry>
        <box size="0.03 0.03 0.03"/>
      </geometry>
      <material name="green">
        <color rgba="0.05 0.2 0.0 1.0"/>
      </material>
    </visual>
    <collision>
      <geometry>
        <box size="0.03 0.03 0.03"/>
      </geometry>
    </collision>
    <inertial>
      <mass value="0.08"/>
      <origin rpy="0 0 0" xyz="0 0 0"/>
      <inertia ixx="0.000006" ixy="0.0" ixz="0.0" iyy="0.000006" iyz="0.0" izz="0.000006"/>
    </inertial>
  </link>
  <!-- Joints -->
  <joint name="base_joint" type="fixed">
    <parent link="base_link"/>
    <child link="base_footprint"/>
    <origin rpy="0.0 0.0 0.0" xyz="0.0 0.0 0.0"/>
  </joint>
  <link name="left_wheel">
    <visual>
      <geometry>
        <cylinder length="0.01" radius="0.016"/>
      </geometry>
      <material name="black">
        <color rgba="0.1 0.1 0.1 1.0"/>
      </material>
    </visual>
    <inertial>
      <mass value="0.05"/>
      <origin rpy="0 0 0" xyz="0 0 0"/>
      <inertia ixx="0.000007" ixy="0.0" ixz="0.0" iyy="0.000007" iyz="0.0" izz="0.000007"/>
    </inertial>
  </link>
  <joint name="left_wheel_joint" type="continuous">
    <parent link="base_link"/>
    <child link="left_wheel"/>
    <origin rpy="1.57079633 0.0 0.0" xyz="0.1 0.04 0.008"/>
    <axis xyz="0 0 1"/>
  </joint>
  <link name="right_wheel">
    <visual>
      <geometry>
        <cylinder length="0.01" radius="0.016"/>
      </geometry>
      <material name="black">
        <color rgba="0.1 0.1 0.1 1.0"/>
      </material>
    </visual>
    <inertial>
      <mass value="0.05"/>
      <origin rpy="0 0 0" xyz="0 0 0"/>
      <inertia ixx="0.000007" ixy="0.0" ixz="0.0" iyy="0.000007" iyz="0.0" izz="0.000007"/>
    </inertial>
  </link>
  <joint name="right_wheel_joint" type="continuous">
    <parent link="base_link"/>
    <child link="right_wheel"/>
    <origin rpy="1.57079633 0.0 0.0" xyz="0.1 -0.04 0.008"/>
    <axis xyz="0 0 1"/>
  </joint>
  <joint name="caster_joint" type="fixed">
    <parent link="base_link"/>
    <child link="caster"/>
    <origin rpy="0.0 0.0 0.0" xyz="-0.12 0.0 0.008"/>
  </joint>
  <joint name="head_joint" type="fixed">
    <parent link="base_link"/>
    <child link="head"/>
    <origin rpy="0.0 0.0 0.0" xyz="-0.2 0.0 0.058"/>
  </joint>
  <joint name="beak_joint" type="fixed">
    <parent link="head"/>
    <child link="beak"/>
    <origin rpy="0.0 0.0 0.0" xyz="-0.05 0.0 0.0"/>
  </joint>
  <link name="left_eye">
    <visual>
      <geometry>
        <sphere radius="0.008"/>
      </geometry>
      <material name="white">
        <color rgba="1.0 1.0 1.0 1"/>
      </material>
    </visual>
    <inertial>
      <mass value="0.001"/>
      <origin rpy="0 0 0" xyz="0 0 0"/>
      <inertia ixx="0.00000003" ixy="0.0" ixz="0.0" iyy="0.00000003" iyz="0.0" izz="0.00000003"/>
    </inertial>
  </link>
  <joint name="left_eye_joint" type="fixed">
    <parent link="head"/>
    <child link="left_eye"/>
    <origin rpy="0.0 0.0 0.0" xyz="-0.04 0.02 0.02"/>
  </joint>
  <link name="right_eye">
    <visual>
      <geometry>
        <sphere radius="0.008"/>
      </geometry>
      <material name="white">
        <color rgba="1.0 1.0 1.0 1"/>
      </material>
    </visual>
    <inertial>
      <mass value="0.001"/>
      <origin rpy="0 0 0" xyz="0 0 0"/>
      <inertia ixx="0.00000003" ixy="0.0" ixz="0.0" iyy="0.00000003" iyz="0.0" izz="0.00000003"/>
    </inertial>
  </link>
  <joint name="right_eye_joint" type="fixed">
    <parent link="head"/>
    <child link="right_eye"/>
    <origin rpy="0.0 0.0 0.0" xyz="-0.04 -0.02 0.02"/>
  </joint>
  <link name="left_foot">
    <visual>
      <geometry>
        <box size="0.015 0.04 0.05"/>
      </geometry>
      <material name="orange">
        <color rgba="1.0 0.6 0.0 1.0"/>
      </material>
    </visual>
    <collision>
      <geometry>
        <box size="0.015 0.04 0.05"/>
      </geometry>
    </collision>
    <inertial>
      <mass value="0.02"/>
      <origin rpy="0 0 0" xyz="0 0 0"/>
      <inertia ixx="0.000002" ixy="0.0" ixz="0.0" iyy="0.0000004" iyz="0.0" izz="0.000002"/>
    </inertial>
  </link>
  <joint name="left_foot_joint" type="fixed">
    <parent link="base_link"/>
    <child link="left_foot"/>
    <origin rpy="0.0 0.0 0.0" xyz="0.185 0.05 0.058"/>
  </joint>
  <link name="right_foot">
    <visual>
      <geometry>
        <box size="0.015 0.04 0.05"/>
      </geometry>
      <material name="orange">
        <color rgba="1.0 0.6 0.0 1.0"/>
      </material>
    </visual>
    <collision>
      <geometry>
        <box size="0.015 0.04 0.05"/>
      </geometry>
    </collision>
    <inertial>
      <mass value="0.02"/>
      <origin rpy="0 0 0" xyz="0 0 0"/>
      <inertia ixx="0.000002" ixy="0.0" ixz="0.0" iyy="0.0000004" iyz="0.0" izz="0.000002"/>
    </inertial>
  </link>
  <joint name="right_foot_joint" type="fixed">
    <parent link="base_link"/>
    <child link="right_foot"/>
    <origin rpy="0.0 0.0 0.0" xyz="0.185 -0.05 0.058"/>
  </joint>
  <link name="left_wing">
    <visual>
      <geometry>
        <box size="0.2 0.02 0.08"/>
      </geometry>
      <material name="black">
        <color rgba="0.1 0.1 0.1 1.0"/>
      </material>
    </visual>
    <collision>
      <geometry>
        <box size="0.2 0.02 0.08"/>
      </geometry>
    </collision>
    <inertial>
      <mass value="0.1"/>
      <origin rpy="0 0 0" xyz="0 0 0"/>
      <inertia ixx="0.00006" ixy="0.0" ixz="0.0" iyy="0.00034" iyz="0.0" izz="0.00034"/>
    </inertial>
  </link>
  <joint name="left_wing_joint" type="fixed">
    <parent link="base_link"/>
    <child link="left_wing"/>
    <origin rpy="0.0 0.0 0.0" xyz="0.0 0.09 0.058"/>
  </joint>
  <link name="right_wing">
    <visual>
      <geometry>
        <box size="0.2 0.02 0.08"/>
      </geometry>
      <material name="black">
        <color rgba="0.1 0.1 0.1 1.0"/>
      </material>
    </visual>
    <collision>
      <geometry>
        <box size="0.2 0.02 0.08"/>
      </geometry>
    </collision>
    <inertial>
      <mass value="0.1"/>
      <origin rpy="0 0 0" xyz="0 0 0"/>
      <inertia ixx="0.00006" ixy="0.0" ixz="0.0" iyy="0.00034" iyz="0.0" izz="0.00034"/>
    </inertial>
  </link>
  <joint name="right_wing_joint" type="fixed">
    <parent link="base_link"/>
    <child link="right_wing"/>
    <origin rpy="0.0 0.0 0.0" xyz="0.0 -0.09 0.058"/>
  </joint>
  <joint name="tail_joint" type="fixed">
    <parent link="base_link"/>
    <child link="tail"/>
    <origin rpy="0.0 0.0 0.0" xyz="0.2 0.0 0.103"/>
  </joint>
  <joint name="rpg_joint" type="fixed">
    <parent link="base_link"/>
    <child link="rpg_base"/>
    <origin rpy="0.0 0.0 0.785398" xyz="0.0 0.0 0.123"/>
  </joint>
  <joint name="rpg_front_joint" type="fixed">
    <parent link="rpg_base"/>
    <child link="rpg_front"/>
    <origin rpy="0.0 0.0 0.0" xyz="-0.125 0.0 0.0"/>
  </joint>
</robot>
